INFO     log:logger_util.py:71 ------------测试开始------------
INFO     log:logger_util.py:71 ------------测试开始------------
INFO     log:logger_util.py:71 接口名称: clientId为空
INFO     log:logger_util.py:71 请求方式: post
INFO     log:logger_util.py:71 请求路径: http://192.168.2.129:8088/common/getToken
INFO     log:logger_util.py:71 请求头为空
INFO     log:logger_util.py:71 请求data参数: {'clientId': '', 'ClientSecret': 'ODZyiyNt0uHY4H9GgrGVT2ocKe84RpaUMTOfYl3ZqF3EYWsn9HKFML6i6GPT', 'timestamp': '1646825027227', 'sign': '5624e408fdbd93f51aaac095c74cfd0b'}
INFO     log:logger_util.py:71 预取结果: [{'equals': {'code': 200}}, {'contains': '$ddt{contains}'}]
INFO     log:logger_util.py:71 实际结果: {'code': 400, 'message': 'clientId错误', 'success': False}
ERROR    log:logger_util.py:67 断言失败：返回的结果中不包含$ddt{contains}
INFO     log:logger_util.py:71 请求接口失败
INFO     log:logger_util.py:71 ------------测试结束------------

ERROR    log:logger_util.py:67 判断断言assert_result异常: Traceback (most recent call last):
  File "D:\Desktop\1\API\common\requests_util.py", line 184, in assert_result
    flag = self.contains_assert(value, sj_result)
  File "D:\Desktop\1\API\common\requests_util.py", line 220, in contains_assert
    error_log("断言失败：返回的结果中不包含" + str(value))
  File "D:\Desktop\1\API\common\logger_util.py", line 68, in error_log
    raise Exception(message)
Exception: 断言失败：返回的结果中不包含$ddt{contains}

ERROR    log:logger_util.py:67 规范yaml测试用例standard_yaml异常: Traceback (most recent call last):
  File "D:\Desktop\1\API\common\requests_util.py", line 184, in assert_result
    flag = self.contains_assert(value, sj_result)
  File "D:\Desktop\1\API\common\requests_util.py", line 220, in contains_assert
    error_log("断言失败：返回的结果中不包含" + str(value))
  File "D:\Desktop\1\API\common\logger_util.py", line 68, in error_log
    raise Exception(message)
Exception: 断言失败：返回的结果中不包含$ddt{contains}

During handling of the above exception, another exception occurred:

Traceback (most recent call last):
  File "D:\Desktop\1\API\common\requests_util.py", line 273, in md5_yaml
    self.assert_result(caseinfo['validate'], results_json, return_code)
  File "D:\Desktop\1\API\common\requests_util.py", line 194, in assert_result
    error_log("判断断言assert_result异常: %s" % str(traceback.format_exc()))
  File "D:\Desktop\1\API\common\logger_util.py", line 68, in error_log
    raise Exception(message)
Exception: 判断断言assert_result异常: Traceback (most recent call last):
  File "D:\Desktop\1\API\common\requests_util.py", line 184, in assert_result
    flag = self.contains_assert(value, sj_result)
  File "D:\Desktop\1\API\common\requests_util.py", line 220, in contains_assert
    error_log("断言失败：返回的结果中不包含" + str(value))
  File "D:\Desktop\1\API\common\logger_util.py", line 68, in error_log
    raise Exception(message)
Exception: 断言失败：返回的结果中不包含$ddt{contains}