INFO     log:logger_util.py:71 ------------测试开始------------
INFO     log:logger_util.py:71 ------------测试开始------------
INFO     log:logger_util.py:71 接口名称: 成功登录api获取token
INFO     log:logger_util.py:71 请求方式: post
INFO     log:logger_util.py:71 请求路径: http://192.168.2.129:8088/common/getToken
INFO     log:logger_util.py:71 请求头为空
INFO     log:logger_util.py:71 请求data参数: {'clientId': '5WV4dG5MKGw2oIDZvvtnaQsnBIwU025E', 'ClientSecret': 'ODZyiyNt0uHY4H9GgrGVT2ocKe84RpaUMTOfYl3ZqF3EYWsn9HKFML6i6GPT', 'timestamp': '1646825015823', 'sign': '27e7249ac2372635129c7c887733acdf'}
INFO     log:logger_util.py:71 预取结果: [{'equals': {'code': 400}}, {'contains': '$ddt{contains}'}]
INFO     log:logger_util.py:71 实际结果: {'code': 200, 'message': '成功', 'data': {'accessToken': '40c61b82f8d44f1095f7b8367db4be77'}, 'success': True}
ERROR    log:logger_util.py:67 断言失败：状态码不等于200
INFO     log:logger_util.py:71 请求接口失败
INFO     log:logger_util.py:71 ------------测试结束------------

ERROR    log:logger_util.py:67 判断断言assert_result异常: Traceback (most recent call last):
  File "D:\Desktop\1\API\common\requests_util.py", line 181, in assert_result
    flag = self.equals_assert(value, sj_result, return_code)
  File "D:\Desktop\1\API\common\requests_util.py", line 203, in equals_assert
    error_log("断言失败：状态码不等于%s" % return_code)
  File "D:\Desktop\1\API\common\logger_util.py", line 68, in error_log
    raise Exception(message)
Exception: 断言失败：状态码不等于200

ERROR    log:logger_util.py:67 规范yaml测试用例standard_yaml异常: Traceback (most recent call last):
  File "D:\Desktop\1\API\common\requests_util.py", line 181, in assert_result
    flag = self.equals_assert(value, sj_result, return_code)
  File "D:\Desktop\1\API\common\requests_util.py", line 203, in equals_assert
    error_log("断言失败：状态码不等于%s" % return_code)
  File "D:\Desktop\1\API\common\logger_util.py", line 68, in error_log
    raise Exception(message)
Exception: 断言失败：状态码不等于200

During handling of the above exception, another exception occurred:

Traceback (most recent call last):
  File "D:\Desktop\1\API\common\requests_util.py", line 273, in md5_yaml
    self.assert_result(caseinfo['validate'], results_json, return_code)
  File "D:\Desktop\1\API\common\requests_util.py", line 194, in assert_result
    error_log("判断断言assert_result异常: %s" % str(traceback.format_exc()))
  File "D:\Desktop\1\API\common\logger_util.py", line 68, in error_log
    raise Exception(message)
Exception: 判断断言assert_result异常: Traceback (most recent call last):
  File "D:\Desktop\1\API\common\requests_util.py", line 181, in assert_result
    flag = self.equals_assert(value, sj_result, return_code)
  File "D:\Desktop\1\API\common\requests_util.py", line 203, in equals_assert
    error_log("断言失败：状态码不等于%s" % return_code)
  File "D:\Desktop\1\API\common\logger_util.py", line 68, in error_log
    raise Exception(message)
Exception: 断言失败：状态码不等于200